Workbook

Sheet 部门汇总
A1: XX 科技有限公司 — 2025年部门人员薪酬汇总
A2: 部门 | B2: 人数 | C2: 应发合计 | D2: 社保个人合计 | E2: 个税合计 | F2: 实发合计 | G2: 社保公司合计 | H2: 公积金个人 | I2: 公积金公司
A3: 研发部 | B3: =COUNTIF(薪酬统计!C:C,A3) -> 4 | C3: =SUMIF(薪酬统计!C:C,A3,薪酬统计!H:H) -> 82500 | D3: =SUMIF(薪酬统计!C:C,A3,薪酬统计!I:I) -> 4830 | E3: =SUMIF(薪酬统计!C:C,A3,薪酬统计!J:J) -> 1730.1 | F3: =SUMIF(薪酬统计!C:C,A3,薪酬统计!K:K) -> 75939.9 | G3: =SUMIF(社保明细!C:C,A3,社保明细!D:D)+SUMIF(社保明细!C:C,A3,社保明细!F:F)+SUMIF(社保明细!C:C,A3,社保明细!H:H)+SUMIF(社保明细!C:C,A3,社保明细!J:J)+SUMIF(社保明细!C:C,A3,社保明细!K:K) -> 11822 | H3: =SUMIF(社保明细!C:C,A3,社保明细!N:N) -> 5520 | I3: =SUMIF(社保明细!C:C,A3,社保明细!M:M) -> 5520
A4: 市场部 | B4: =COUNTIF(薪酬统计!C:C,A4) -> 3 | C4: =SUMIF(薪酬统计!C:C,A4,薪酬统计!H:H) -> 60500 | D4: =SUMIF(薪酬统计!C:C,A4,薪酬统计!I:I) -> 3255 | E4: =SUMIF(薪酬统计!C:C,A4,薪酬统计!J:J) -> 1267.35 | F4: =SUMIF(薪酬统计!C:C,A4,薪酬统计!K:K) -> 55977.65 | G4: =SUMIF(社保明细!C:C,A4,社保明细!D:D)+SUMIF(社保明细!C:C,A4,社保明细!F:F)+SUMIF(社保明细!C:C,A4,社保明细!H:H)+SUMIF(社保明细!C:C,A4,社保明细!J:J)+SUMIF(社保明细!C:C,A4,社保明细!K:K) -> 7967 | H4: =SUMIF(社保明细!C:C,A4,社保明细!N:N) -> 3720 | I4: =SUMIF(社保明细!C:C,A4,社保明细!M:M) -> 3720
A5: 财务部 | B5: =COUNTIF(薪酬统计!C:C,A5) -> 3 | C5: =SUMIF(薪酬统计!C:C,A5,薪酬统计!H:H) -> 47000 | D5: =SUMIF(薪酬统计!C:C,A5,薪酬统计!I:I) -> 2887.5 | E5: =SUMIF(薪酬统计!C:C,A5,薪酬统计!J:J) -> 873.38 | F5: =SUMIF(薪酬统计!C:C,A5,薪酬统计!K:K) -> 43239.12 | G5: =SUMIF(社保明细!C:C,A5,社保明细!D:D)+SUMIF(社保明细!C:C,A5,社保明细!F:F)+SUMIF(社保明细!C:C,A5,社保明细!H:H)+SUMIF(社保明细!C:C,A5,社保明细!J:J)+SUMIF(社保明细!C:C,A5,社保明细!K:K) -> 7067.5 | H5: =SUMIF(社保明细!C:C,A5,社保明细!N:N) -> 3300 | I5: =SUMIF(社保明细!C:C,A5,社保明细!M:M) -> 3300
A6: 人事部 | B6: =COUNTIF(薪酬统计!C:C,A6) -> 2 | C6: =SUMIF(薪酬统计!C:C,A6,薪酬统计!H:H) -> 33500 | D6: =SUMIF(薪酬统计!C:C,A6,薪酬统计!I:I) -> 2047.5 | E6: =SUMIF(薪酬统计!C:C,A6,薪酬统计!J:J) -> 643.58 | F6: =SUMIF(薪酬统计!C:C,A6,薪酬统计!K:K) -> 30808.92 | G6: =SUMIF(社保明细!C:C,A6,社保明细!D:D)+SUMIF(社保明细!C:C,A6,社保明细!F:F)+SUMIF(社保明细!C:C,A6,社保明细!H:H)+SUMIF(社保明细!C:C,A6,社保明细!J:J)+SUMIF(社保明细!C:C,A6,社保明细!K:K) -> 5011.5 | H6: =SUMIF(社保明细!C:C,A6,社保明细!N:N) -> 2340 | I6: =SUMIF(社保明细!C:C,A6,社保明细!M:M) -> 2340
A7: 运营部 | B7: =COUNTIF(薪酬统计!C:C,A7) -> 3 | C7: =SUMIF(薪酬统计!C:C,A7,薪酬统计!H:H) -> 44000 | D7: =SUMIF(薪酬统计!C:C,A7,薪酬统计!I:I) -> 2625 | E7: =SUMIF(薪酬统计!C:C,A7,薪酬统计!J:J) -> 791.25 | F7: =SUMIF(薪酬统计!C:C,A7,薪酬统计!K:K) -> 40583.75 | G7: =SUMIF(社保明细!C:C,A7,社保明细!D:D)+SUMIF(社保明细!C:C,A7,社保明细!F:F)+SUMIF(社保明细!C:C,A7,社保明细!H:H)+SUMIF(社保明细!C:C,A7,社保明细!J:J)+SUMIF(社保明细!C:C,A7,社保明细!K:K) -> 6425 | H7: =SUMIF(社保明细!C:C,A7,社保明细!N:N) -> 3000 | I7: =SUMIF(社保明细!C:C,A7,社保明细!M:M) -> 3000
A8: 合 计 | B8: =SUM(B3:B7) -> 15 | C8: =SUM(C3:C7) -> 267500 | D8: =SUM(D3:D7) -> 15645 | E8: =SUM(E3:E7) -> 5305.66 | F8: =SUM(F3:F7) -> 246549.34 | G8: =SUM(G3:G7) -> 38293 | H8: =SUM(H3:H7) -> 17880 | I8: =SUM(I3:I7) -> 17880

Sheet 数据透视
A1: XX 科技有限公司 — 2025年各部门薪酬数据透视
A2: ▌ 薪酬汇总（按部门）
A3: 行标签
A4: 财务部
A5: 10000
A6: 9187.97
A7: 129.53
A8: 12500
A9: 11460.2
A10: 199.8
A11: 24500
A12: 22590.95
A13: 544.05
A14: 人事部
A15: 12000
A16: 11026.12
A17: 186.38
A18: 21500
A19: 19782.8
A20: 457.2
A21: 市场部
A22: 11500
A23: 10592.05
A24: 172.95
A25: 19500
A26: 18046.5
A27: 403.5
A28: 29500
A29: 27339.1
A30: 690.9
A31: 研发部
A32: 14500
A33: 13298.35
A34: 256.65
A35: 16500
A36: 15136.5
A37: 313.5
A38: 22000
A39: 20267.8
A40: 472.2
...

Sheet 社保明细
A1: XX 科技有限公司 — 2025年社保公积金明细
A2: 编号 | B2: 姓名 | C2: 部门 | D2: 养老保险 | F2: 医疗保险 | H2: 失业保险 | J2: 工伤保险 | K2: 生育保险 | M2: 住房公积金 | O2: 社保合计 | P2: 公积金合计
A3: 编号 | B3: 姓名 | C3: 部门 | D3: 养老(单位16%) | E3: 养老(个人8%) | F3: 医疗(单位8%) | G3: 医疗(个人2%) | H3: 失业(单位0.5%) | I3: 失业(个人0.5%) | J3: 工伤(单位0.4%) | K3: 生育(单位0.8%) | M3: 公积金(单位12%) | N3: 公积金(个人12%) | O3: 社保合计(个人) | P3: 公积金合计(个人)
A4: E001 | B4: 张明 | C4: 研发部 | D4: 2400 | E4: 1200 | F4: 1200 | G4: 300 | H4: 75 | I4: 75 | J4: 60 | K4: 120 | M4: 1800 | N4: 1800 | O4: =E4+G4+I4 -> 1575 | P4: =N4 -> 1800
A5: E002 | B5: 李娜 | C5: 研发部 | D5: 1920 | E5: 960 | F5: 960 | G5: 240 | H5: 60 | I5: 60 | J5: 48 | K5: 96 | M5: 1440 | N5: 1440 | O5: =E5+G5+I5 -> 1260 | P5: =N5 -> 1440
A6: E003 | B6: 王强 | C6: 研发部 | D6: 1600 | E6: 800 | F6: 800 | G6: 200 | H6: 50 | I6: 50 | J6: 40 | K6: 80 | M6: 1200 | N6: 1200 | O6: =E6+G6+I6 -> 1050 | P6: =N6 -> 1200
A7: E004 | B7: 赵磊 | C7: 研发部 | D7: 1440 | E7: 720 | F7: 720 | G7: 180 | H7: 45 | I7: 45 | J7: 36 | K7: 72 | M7: 1080 | N7: 1080 | O7: =E7+G7+I7 -> 945 | P7: =N7 -> 1080
A8: E005 | B8: 陈静 | C8: 市场部 | D8: 2240 | E8: 1120 | F8: 1120 | G8: 280 | H8: 70 | I8: 70 | J8: 56 | K8: 112 | M8: 1680 | N8: 1680 | O8: =E8+G8+I8 -> 1470 | P8: =N8 -> 1680
A9: E006 | B9: 刘洋 | C9: 市场部 | D9: 1600 | E9: 800 | F9: 800 | G9: 200 | H9: 50 | I9: 50 | J9: 40 | K9: 80 | M9: 1200 | N9: 1200 | O9: =E9+G9+I9 -> 1050 | P9: =N9 -> 1200
A10: E007 | B10: 孙芳 | C10: 市场部 | D10: 1120 | E10: 560 | F10: 560 | G10: 140 | H10: 35 | I10: 35 | J10: 28 | K10: 56 | M10: 840 | N10: 840 | O10: =E10+G10+I10 -> 735 | P10: =N10 -> 840
A11: E008 | B11: 周涛 | C11: 财务部 | D11: 2080 | E11: 1040 | F11: 1040 | G11: 260 | H11: 65 | I11: 65 | J11: 52 | K11: 104 | M11: 1560 | N11: 1560 | O11: =E11+G11+I11 -> 1365 | P11: =N11 -> 1560
A12: E009 | B12: 吴梅 | C12: 财务部 | D12: 1280 | E12: 640 | F12: 640 | G12: 160 | H12: 40 | I12: 40 | J12: 32 | K12: 64 | M12: 960 | N12: 960 | O12: =E12+G12+I12 -> 840 | P12: =N12 -> 960
A13: E010 | B13: 郑华 | C13: 财务部 | D13: 1040 | E13: 520 | F13: 520 | G13: 130 | H13: 32.5 | I13: 32.5 | J13: 26 | K13: 52 | M13: 780 | N13: 780 | O13: =E13+G13+I13 -> 682.5 | P13: =N13 -> 780
A14: E011 | B14: 冯丽 | C14: 人事部 | D14: 1920 | E14: 960 | F14: 960 | G14: 240 | H14: 60 | I14: 60 | J14: 48 | K14: 96 | M14: 1440 | N14: 1440 | O14: =E14+G14+I14 -> 1260 | P14: =N14 -> 1440
A15: E012 | B15: 陈刚 | C15: 人事部 | D15: 1200 | E15: 600 | F15: 600 | G15: 150 | H15: 37.5 | I15: 37.5 | J15: 30 | K15: 60 | M15: 900 | N15: 900 | O15: =E15+G15+I15 -> 787.5 | P15: =N15 -> 900
... A18: E015 | B18: 蒋涛 | C18: 运营部 | D18: 1120 | E18: 560 | F18: 560 | G18: 140 | H18: 35 | I18: 35 | J18: 28 | K18: 56 | M18: 840 | N18: 840 | O18: =E18+G18+I18 -> 735 | P18: =N18 -> 840
C19: 合 计 | D19: =SUM(D4:D18) -> 23840 | E19: =SUM(E4:E18) -> 11920 | F19: =SUM(F4:F18) -> 11920 | G19: =SUM(G4:G18) -> 2980 | H19: =SUM(H4:H18) -> 745 | I19: =SUM(I4:I18) -> 745 | J19: =SUM(J4:J18) -> 596 | K19: =SUM(K4:K18) -> 1192 | M19: =SUM(M4:M18) -> 17880 | N19: =SUM(N4:N18) -> 17880 | O19: =SUM(O4:O18) -> 15645 | P19: =SUM(P4:P18) -> 17880

Sheet 薪酬统计
A1: XX 科技有限公司 — 2025年薪酬统计表
A2: 编号 | B2: 姓名 | C2: 部门 | D2: 基本工资 | E2: 岗位工资 | F2: 绩效工资 | G2: 餐补/交补 | H2: 应发合计 | I2: 社保个人 | J2: 个人所得税 | K2: 实发工资
A3: E001 | B3: 张明 | C3: 研发部 | D3: 15000 | E3: 8000 | F3: 6000 | G3: 500 | H3: =D3+E3+F3+G3 -> 29500 | I3: =ROUND(D3*0.105,2) -> 1575 | J3: =MAX(0,ROUND(IF(H3-ROUND(D3*0.105,2)-5000<=0,0,IF(H3-ROUND(D3*0.105,2)-5000<=36000,(H3-ROUND(D3*0.105,2)-5000)*0.03,IF(H3-ROUND(D3*0.105,2)-5000<=144000,(H3-ROUND(D3*0.105,2)-5000)*0.1-2520,(H3-ROUND(D3*0.105,2)-5000)*0.2-16920))),2)) -> 687.75 | K3: =H3-I3-J3 -> 27237.25
A4: E002 | B4: 李娜 | C4: 研发部 | D4: 12000 | E4: 5000 | F4: 4500 | G4: 500 | H4: =D4+E4+F4+G4 -> 22000 | I4: =ROUND(D4*0.105,2) -> 1260 | J4: =MAX(0,ROUND(IF(H4-ROUND(D4*0.105,2)-5000<=0,0,IF(H4-ROUND(D4*0.105,2)-5000<=36000,(H4-ROUND(D4*0.105,2)-5000)*0.03,IF(H4-ROUND(D4*0.105,2)-5000<=144000,(H4-ROUND(D4*0.105,2)-5000)*0.1-2520,(H4-ROUND(D4*0.105,2)-5000)*0.2-16920))),2)) -> 472.2 | K4: =H4-I4-J4 -> 20267.8
A5: E003 | B5: 王强 | C5: 研发部 | D5: 10000 | E5: 3000 | F5: 3000 | G5: 500 | H5: =D5+E5+F5+G5 -> 16500 | I5: =ROUND(D5*0.105,2) -> 1050 | J5: =MAX(0,ROUND(IF(H5-ROUND(D5*0.105,2)-5000<=0,0,IF(H5-ROUND(D5*0.105,2)-5000<=36000,(H5-ROUND(D5*0.105,2)-5000)*0.03,IF(H5-ROUND(D5*0.105,2)-5000<=144000,(H5-ROUND(D5*0.105,2)-5000)*0.1-2520,(H5-ROUND(D5*0.105,2)-5000)*0.2-16920))),2)) -> 313.5 | K5: =H5-I5-J5 -> 15136.5
A6: E004 | B6: 赵磊 | C6: 研发部 | D6: 9000 | E6: 2500 | F6: 2500 | G6: 500 | H6: =D6+E6+F6+G6 -> 14500 | I6: =ROUND(D6*0.105,2) -> 945 | J6: =MAX(0,ROUND(IF(H6-ROUND(D6*0.105,2)-5000<=0,0,IF(H6-ROUND(D6*0.105,2)-5000<=36000,(H6-ROUND(D6*0.105,2)-5000)*0.03,IF(H6-ROUND(D6*0.105,2)-5000<=144000,(H6-ROUND(D6*0.105,2)-5000)*0.1-2520,(H6-ROUND(D6*0.105,2)-5000)*0.2-16920))),2)) -> 256.65 | K6: =H6-I6-J6 -> 13298.35
A7: E005 | B7: 陈静 | C7: 市场部 | D7: 14000 | E7: 7000 | F7: 8000 | G7: 500 | H7: =D7+E7+F7+G7 -> 29500 | I7: =ROUND(D7*0.105,2) -> 1470 | J7: =MAX(0,ROUND(IF(H7-ROUND(D7*0.105,2)-5000<=0,0,IF(H7-ROUND(D7*0.105,2)-5000<=36000,(H7-ROUND(D7*0.105,2)-5000)*0.03,IF(H7-ROUND(D7*0.105,2)-5000<=144000,(H7-ROUND(D7*0.105,2)-5000)*0.1-2520,(H7-ROUND(D7*0.105,2)-5000)*0.2-16920))),2)) -> 690.9 | K7: =H7-I7-J7 -> 27339.1
A8: E006 | B8: 刘洋 | C8: 市场部 | D8: 10000 | E8: 4000 | F8: 5000 | G8: 500 | H8: =D8+E8+F8+G8 -> 19500 | I8: =ROUND(D8*0.105,2) -> 1050 | J8: =MAX(0,ROUND(IF(H8-ROUND(D8*0.105,2)-5000<=0,0,IF(H8-ROUND(D8*0.105,2)-5000<=36000,(H8-ROUND(D8*0.105,2)-5000)*0.03,IF(H8-ROUND(D8*0.105,2)-5000<=144000,(H8-ROUND(D8*0.105,2)-5000)*0.1-2520,(H8-ROUND(D8*0.105,2)-5000)*0.2-16920))),2)) -> 403.5 | K8: =H8-I8-J8 -> 18046.5
A9: E007 | B9: 孙芳 | C9: 市场部 | D9: 7000 | E9: 2000 | F9: 2000 | G9: 500 | H9: =D9+E9+F9+G9 -> 11500 | I9: =ROUND(D9*0.105,2) -> 735 | J9: =MAX(0,ROUND(IF(H9-ROUND(D9*0.105,2)-5000<=0,0,IF(H9-ROUND(D9*0.105,2)-5000<=36000,(H9-ROUND(D9*0.105,2)-5000)*0.03,IF(H9-ROUND(D9*0.105,2)-5000<=144000,(H9-ROUND(D9*0.105,2)-5000)*0.1-2520,(H9-ROUND(D9*0.105,2)-5000)*0.2-16920))),2)) -> 172.95 | K9: =H9-I9-J9 -> 10592.05
A10: E008 | B10: 周涛 | C10: 财务部 | D10: 13000 | E10: 6000 | F10: 5000 | G10: 500 | H10: =D10+E10+F10+G10 -> 24500 | I10: =ROUND(D10*0.105,2) -> 1365 | J10: =MAX(0,ROUND(IF(H10-ROUND(D10*0.105,2)-5000<=0,0,IF(H10-ROUND(D10*0.105,2)-5000<=36000,(H10-ROUND(D10*0.105,2)-5000)*0.03,IF(H10-ROUND(D10*0.105,2)-5000<=144000,(H10-ROUND(D10*0.105,2)-5000)*0.1-2520,(H10-ROUND(D10*0.105,2)-5000)*0.2-16920))),2)) -> 544.05 | K10: =H10-I10-J10 -> 22590.95
A11: E009 | B11: 吴梅 | C11: 财务部 | D11: 8000 | E11: 2000 | F11: 2000 | G11: 500 | H11: =D11+E11+F11+G11 -> 12500 | I11: =ROUND(D11*0.105,2) -> 840 | J11: =MAX(0,ROUND(IF(H11-ROUND(D11*0.105,2)-5000<=0,0,IF(H11-ROUND(D11*0.105,2)-5000<=36000,(H11-ROUND(D11*0.105,2)-5000)*0.03,IF(H11-ROUND(D11*0.105,2)-5000<=144000,(H11-ROUND(D11*0.105,2)-5000)*0.1-2520,(H11-ROUND(D11*0.105,2)-5000)*0.2-16920))),2)) -> 199.8 | K11: =H11-I11-J11 -> 11460.2
A12: E010 | B12: 郑华 | C12: 财务部 | D12: 6500 | E12: 1500 | F12: 1500 | G12: 500 | H12: =D12+E12+F12+G12 -> 10000 | I12: =ROUND(D12*0.105,2) -> 682.5 | J12: =MAX(0,ROUND(IF(H12-ROUND(D12*0.105,2)-5000<=0,0,IF(H12-ROUND(D12*0.105,2)-5000<=36000,(H12-ROUND(D12*0.105,2)-5000)*0.03,IF(H12-ROUND(D12*0.105,2)-5000<=144000,(H12-ROUND(D12*0.105,2)-5000)*0.1-2520,(H12-ROUND(D12*0.105,2)-5000)*0.2-16920))),2)) -> 129.53 | K12: =H12-I12-J12 -> 9187.97
A13: E011 | B13: 冯丽 | C13: 人事部 | D13: 12000 | E13: 5000 | F13: 4000 | G13: 500 | H13: =D13+E13+F13+G13 -> 21500 | I13: =ROUND(D13*0.105,2) -> 1260 | J13: =MAX(0,ROUND(IF(H13-ROUND(D13*0.105,2)-5000<=0,0,IF(H13-ROUND(D13*0.105,2)-5000<=36000,(H13-ROUND(D13*0.105,2)-5000)*0.03,IF(H13-ROUND(D13*0.105,2)-5000<=144000,(H13-ROUND(D13*0.105,2)-5000)*0.1-2520,(H13-ROUND(D13*0.105,2)-5000)*0.2-16920))),2)) -> 457.2 | K13: =H13-I13-J13 -> 19782.8
A14: E012 | B14: 陈刚 | C14: 人事部 | D14: 7500 | E14: 2000 | F14: 2000 | G14: 500 | H14: =D14+E14+F14+G14 -> 12000 | I14: =ROUND(D14*0.105,2) -> 787.5 | J14: =MAX(0,ROUND(IF(H14-ROUND(D14*0.105,2)-5000<=0,0,IF(H14-ROUND(D14*0.105,2)-5000<=36000,(H14-ROUND(D14*0.105,2)-5000)*0.03,IF(H14-ROUND(D14*0.105,2)-5000<=144000,(H14-ROUND(D14*0.105,2)-5000)*0.1-2520,(H14-ROUND(D14*0.105,2)-5000)*0.2-16920))),2)) -> 186.38 | K14: =H14-I14-J14 -> 11026.12
... A17: E015 | B17: 蒋涛 | C17: 运营部 | D17: 7000 | E17: 2000 | F17: 1500 | G17: 500 | H17: =D17+E17+F17+G17 -> 11000 | I17: =ROUND(D17*0.105,2) -> 735 | J17: =MAX(0,ROUND(IF(H17-ROUND(D17*0.105,2)-5000<=0,0,IF(H17-ROUND(D17*0.105,2)-5000<=36000,(H17-ROUND(D17*0.105,2)-5000)*0.03,IF(H17-ROUND(D17*0.105,2)-5000<=144000,(H17-ROUND(D17*0.105,2)-5000)*0.1-2520,(H17-ROUND(D17*0.105,2)-5000)*0.2-16920))),2)) -> 157.95 | K17: =H17-I17-J17 -> 10107.05
C18: 合 计 | D18: =SUM(D3:D17) -> 149000 | E18: =SUM(E3:E17) -> 57000 | F18: =SUM(F3:F17) -> 54000 | G18: =SUM(G3:G17) -> 7500 | H18: =SUM(H3:H17) -> 267500 | I18: =SUM(I3:I17) -> 15645 | J18: =SUM(J3:J17) -> 5305.66 | K18: =SUM(K3:K17) -> 246549.34

Sheet 花名册
A1: XX 科技有限公司 — 员工花名册（2025年）
A2: 编号 | B2: 姓名 | C2: 部门 | D2: 岗位 | E2: 性别 | F2: 入职日期 | G2: 合同类型 | H2: 状态
A3: E001 | B3: 张明 | C3: 研发部 | D3: 技术总监 | E3: 男 | F3: 43525 | G3: 无固定期限 | H3: 在职
A4: E002 | B4: 李娜 | C4: 研发部 | D4: 高级工程师 | E4: 女 | F4: 43997 | G4: 固定期限 | H4: 在职
A5: E003 | B5: 王强 | C5: 研发部 | D5: 工程师 | E5: 男 | F5: 44440 | G5: 固定期限 | H5: 在职
A6: E004 | B6: 赵磊 | C6: 研发部 | D6: 工程师 | E6: 男 | F6: 44635 | G6: 固定期限 | H6: 在职
A7: E005 | B7: 陈静 | C7: 市场部 | D7: 市场总监 | E7: 女 | F7: 43282 | G7: 无固定期限 | H7: 在职
A8: E006 | B8: 刘洋 | C8: 市场部 | D8: 市场经理 | E8: 男 | F8: 43840 | G8: 固定期限 | H8: 在职
A9: E007 | B9: 孙芳 | C9: 市场部 | D9: 市场专员 | E9: 女 | F9: 44774 | G9: 固定期限 | H9: 在职
A10: E008 | B10: 周涛 | C10: 财务部 | D10: 财务总监 | E10: 男 | F10: 42856 | G10: 无固定期限 | H10: 在职
A11: E009 | B11: 吴梅 | C11: 财务部 | D11: 会计 | E11: 女 | F11: 44287 | G11: 固定期限 | H11: 在职
A12: E010 | B12: 郑华 | C12: 财务部 | D12: 出纳 | E12: 女 | F12: 44936 | G12: 固定期限 | H12: 在职
A13: E011 | B13: 冯丽 | C13: 人事部 | D13: 人事总监 | E13: 女 | F13: 43709 | G13: 无固定期限 | H13: 在职
A14: E012 | B14: 陈刚 | C14: 人事部 | D14: 招聘专员 | E14: 男 | F14: 44713 | G14: 固定期限 | H14: 在职
... A17: E015 | B17: 蒋涛 | C17: 运营部 | D17: 运营专员 | E17: 男 | F17: 45061 | G17: 固定期限 | H17: 在职
